Workbook
Name BSCheck: Model!$F$118
Name L_Scenarios: Scenarios!$D$12:$D$14
Name million: Assumptions!$F$12
Name S_Scenarios: Scenarios!$E$11
Name ScenarioUSed: Scenarios!$D$11

Sheet Cover
C7: Veritas Dwellings
C8: Financial Model for 2025 to 2029
C11: Modeller | D11: Animashaun Jafar
C12: Version | D12: Ver 1.01
C13: Circularity in Model | D13: Interest Expense Line of the P&L

Sheet Historicals FS
B2: Veritas Dwellings
B3: Income Statement
B5: ($ Millions)
G7: 2022 | H7: 2023 | I7: 2024
C9: Gross Revenue | G9: 1553.87 | H9: 1776.88 | I9: 1975.48
C11: Cost of Sales | G11: 980.84 | H11: 1078.03 | I11: 1201.29
C12: SG&A | G12: 265.79 | H12: 290.54 | I12: 305.35
C13: Total Costs | G13: 1246.63 | H13: 1368.57 | I13: 1506.64
C15: Cost Adjustments - Gain/(Loss) | G15: 0 | H15: 0 | I15: 0
C16: EBITDA | G16: 307.24 | H16: 408.31 | I16: 468.84
C18: Depreciation | G18: 25.539 | H18: 32.057 | I18: 38.499
C19: EBIT | G19: 281.701 | H19: 376.253 | I19: 430.341
C21: Interest Expense | G21: 13.304 | H21: 14.263 | I21: 22.055
C22: EBT | G22: 268.397 | H22: 361.99 | I22: 408.286
C24: Current Taxes | G24: 62.432 | H24: 92.477 | I24: 100.457
C25: Deferred Income Taxes | G25: 9.031 | H25: 2.745 | I25: 10.737
... C28: Net Income | G28: 196.934 | H28: 266.768 | I28: 297.092
B30: =B2 -> Veritas Dwellings
B31: Cash Flow Statement
B33: ($ Millions)
G35: 2015 | H35: 2016 | I35: 2017
B36: Operating Activities
C37: Net Income | G37: 196.934 | H37: 266.768 | I37: 297.092
C38: Depreciation | G38: 25.539 | H38: 32.057 | I38: 38.499
C39: Deferred Income Taxes | G39: 9.031 | H39: 2.745 | I39: 10.737
C40: Changes in Working Capital | G40: -5.847 | H40: -19.241 | I40: -2.397
C41: Other | G41: 11.584 | H41: 27.166 | I41: -7.151
C42: Operating Cash Flow | G42: 237.241 | H42: 309.495 | I42: 336.78
B44: Investing Activities
C45: CAPEX | G45: -56.626 | H45: -62.953 | I45: -110.809
C46: Other | G46: 0 | H46: 0 | I46: 0
C47: Investing Cash Flow | G47: -56.626 | H47: -62.953 | I47: -110.809
B49: Financing Activities
C50: Revolver Issuance / (Repayment) | G50: 10 | H50: 0 | I50: 0
C51: Variable Rate Long Term Debt Issuance / (Repayment) | G51: 100 | H51: 80 | I51: 350
C52: Fixed Rate Long Term Debt Issuance / (Repayment) | G52: 0 | H52: 156.67 | I52: -80
C53: Preference Shares Issuance/ (Buy-Back) | G53: 0 | H53: 0 | I53: 0
C54: Common Shares Issuance/ (Buy-Back) | G54: -282.813 | H54: -432.826 | I54: -461.157
C55: Preference Dividends | G55: 0 | H55: 0 | I55: 0
C56: Common Dividends | G56: -27.89 | H56: -30.077 | I56: -31.291
...

Sheet Summary
B2: =Cover!$C$7 -> Veritas Dwellings | I2: ="Financial Forecast: "&L6&" to "&P6 -> Financial Forecast: 2025 to 2029
B3: Summary | I3: =IF(BSCheck=0,"BS Check: OK","BS Check: ERROR") -> BS Check: OK | K3: =ScenarioUSed -> Scenario: Base Case
I5: Actual | J5: Actual | K5: Actual | L5: Forecast | M5: Forecast | N5: Forecast | O5: Forecast | P5: Forecast
E6: Units | F6: Trend | I6: ='Historicals FS'!G7 -> 2022 | J6: ='Historicals FS'!H7 -> 2023 | K6: ='Historicals FS'!I7 -> 2024 | L6: =K6+1 -> 2025 | M6: =L6+1 -> 2026 | N6: =M6+1 -> 2027 | O6: =N6+1 -> 2028 | P6: =O6+1 -> 2029
B8: Analysis Based on : Base Case Scenario
C10: Revenue
D11: Gross Revenue | E11: $'m | I11: 1553.87 | J11: 1776.88 | K11: 1975.48 | L11: 2113.2846 | M11: 2284.545 | N11: 2464.179 | O11: 2623.9274 | P11: 2820.5087
D12: Growth Rate | E12: % | J12: 0.14351908 | K12: 0.11176894 | L12: 0.069757518 | M12: 0.081039907 | N12: 0.078630123 | O12: 0.064828223 | P12: 0.074918756
C13: EBITDA
D14: EBITDA | E14: $'m | I14: 307.24 | J14: 408.31 | K14: 468.84 | L14: 490.46089 | M14: 522.52323 | N14: 553.09649 | O14: 569.28494 | P14: 595.92611
D15: Growth Rate | E15: % | J15: 0.32896107 | K15: 0.14824521 | L15: 0.046115715 | M15: 0.065371852 | N15: 0.058510811 | O15: 0.029268763 | P15: 0.046797612
D16: EBITA Margin | E16: % | I16: 0.19772568 | J16: 0.22979042 | K16: 0.23732966 | L16: 0.23208464 | M16: 0.22872092 | N16: 0.22445467 | O16: 0.21695911 | P16: 0.2112832
C17: Net Profit
D18: Net Profit | E18: $'m | I18: 196.934 | J18: 266.768 | K18: 297.092 | L18: 310.1297 | M18: 328.87209 | N18: 346.77191 | O18: 354.38005 | P18: 368.58605
D19: Growth Rate | E19: % | J19: 0.35460611 | K19: 0.1136718 | L19: 0.043884394 | M19: 0.060434034 | N19: 0.054427894 | O19: 0.021939915 | P19: 0.040086905
D20: Net Profit Margin | E20: % | I20: 0.12673776 | J20: 0.15013282 | K20: 0.15038978 | L20: 0.14675246 | M20: 0.14395518 | N20: 0.14072513 | O20: 0.13505711 | P20: 0.1306807
C21: Dupont Analysis
D22: ROE | E22: % | I22: 0.39893204 | J22: 0.85712725 | K22: 4.4437597 | L22: 0.88205322 | M22: 0.50753633 | N22: 0.36299223 | O22: 0.28005843 | P22: 0.23277436
D23: Net Profit Margin | E23: % | I23: 0.12673776 | J23: 0.15013282 | K23: 0.15038978 | L23: 0.14675246 | M23: 0.14395518 | N23: 0.14072513 | O23: 0.13505711 | P23: 0.1306807
D24: Asset Turnover | E24: times | I24: 1.3639184 | J24: 1.432732 | K24: 1.5489733 | L24: 1.5284396 | M24: 1.56119 | N24: 1.5198875 | O24: 1.4493246 | P24: 1.3715254
D25: Financial Leverage | E25: times | I25: 2.3078336 | J25: 3.9847832 | K25: 19.076044 | L25: 3.9324312 | M25: 2.2583127 | N25: 1.6971266 | O25: 1.4307558 | P25: 1.2987328
B27: Analysis Based on : Best Case Scenario
C29: Revenue
D30: Gross Revenue | E30: $'m | I30: 1553.87 | J30: 1776.88 | K30: 1975.48 | L30: 2160.2361 | M30: 2384.1036 | N30: 2622.4241 | O30: 2846.2607 | P30: 3114.7328
D31: Growth Rate | E31: % | J31: 0.14351908 | K31: 0.11176894 | L31: 0.093524684 | M31: 0.10363102 | N31: 0.099962304 | O31: 0.085354861 | P31: 0.094324462
C32: EBITDA
D33: EBITDA | E33: $'m | I33: 307.24 | J33: 408.31 | K33: 468.84 | L33: 536.12888 | M33: 623.83671 | N33: 717.70335 | O33: 803.74725 | P33: 910.43363
D34: Growth Rate | E34: % | J34: 0.32896107 | K34: 0.14824521 | L34: 0.14352206 | M34: 0.16359466 | N34: 0.15046669 | O34: 0.11988783 | P34: 0.13273623
D35: EBITA Margin | E35: % | I35: 0.19772568 | J35: 0.22979042 | K35: 0.23732966 | L35: 0.24818068 | M35: 0.2616651 | N35: 0.27367936 | O35: 0.28238707 | P35: 0.29229911
C36: Net Profit
D37: Net Profit | E37: $'m | I37: 196.934 | J37: 266.768 | K37: 297.092 | L37: 341.18394 | M37: 397.76526 | N37: 458.70457 | O37: 513.81442 | P37: 582.45116
D38: Growth Rate | E38: % | J38: 0.35460611 | K38: 0.1136718 | L38: 0.14841173 | M38: 0.16583817 | N38: 0.15320422 | O38: 0.12014236 | P38: 0.13358274
D39: Net Profit Margin | E39: % | I39: 0.12673776 | J39: 0.15013282 | K39: 0.15038978 | L39: 0.15793826 | M39: 0.16684059 | N39: 0.17491624 | O39: 0.18052261 | P39: 0.18699876
C40: Dupont Analysis
D41: ROE | E41: % | I41: 0.39893204 | J41: 0.85712725 | K41: 4.4437597 | L41: 0.90633589 | M41: 0.54642937 | N41: 0.40780301 | O41: 0.32885585 | P41: 0.28390212
D42: Net Profit Margin | E42: % | I42: 0.12673776 | J42: 0.15013282 | K42: 0.15038978 | L42: 0.15793826 | M42: 0.16684059 | N42: 0.17491624 | O42: 0.18052261 | P42: 0.18699876
D43: Asset Turnover | E43: times | I43: 1.3639184 | J43: 1.432732 | K43: 1.5489733 | L43: 1.5616992 | M43: 1.5733392 | N43: 1.4643549 | O43: 1.3506839 | P43: 1.2341249
D44: Financial Leverage | E44: times | I44: 2.3078336 | J44: 3.9847832 | K44: 19.076044 | L44: 3.6745524 | M44: 2.0816607 | N44: 1.5921132 | O44: 1.3487151 | P44: 1.230186
B47: Analysis Based on : Worst Case Scenario
C49: Revenue
...

Sheet Assumptions
B2: =Cover!$C$7 -> Veritas Dwellings | I2: ="Financial Forecast: "&L6&" to "&P6 -> Financial Forecast: 2025 to 2029
B3: Inputs & Assumptions | I3: =IF(BSCheck=0,"BS Check: OK","BS Check: ERROR") -> BS Check: OK | K3: =ScenarioUSed -> Scenario: Base Case
I5: Actual | J5: Actual | K5: Actual | L5: Forecast | M5: Forecast | N5: Forecast | O5: Forecast | P5: Forecast
E6: Units | F6: Inputs | I6: ='Historicals FS'!G7 -> 2022 | J6: ='Historicals FS'!H7 -> 2023 | K6: ='Historicals FS'!I7 -> 2024 | L6: =K6+1 -> 2025 | M6: =L6+1 -> 2026 | N6: =M6+1 -> 2027 | O6: =N6+1 -> 2028 | P6: =O6+1 -> 2029
B9: General Assumptions
D11: Days in the Year | I11: =DATE(I6,12,31)-DATE(I6,1,1)+1 -> 365 | J11: =DATE(J6,12,31)-DATE(J6,1,1)+1 -> 365 | K11: =DATE(K6,12,31)-DATE(K6,1,1)+1 -> 366 | L11: =DATE(L6,12,31)-DATE(L6,1,1)+1 -> 365 | M11: =DATE(M6,12,31)-DATE(M6,1,1)+1 -> 365 | N11: =DATE(N6,12,31)-DATE(N6,1,1)+1 -> 365 | O11: =DATE(O6,12,31)-DATE(O6,1,1)+1 -> 366 | P11: =DATE(P6,12,31)-DATE(P6,1,1)+1 -> 365
D12: Millions | E12: Constant | F12: 1000000
C14: Style Guide
D16: Number | E16: Number | F16: 1234.5
D17: Input | E17: Number
D18: Percent | E18: Percent | F18: 0.23
D19: Multiples | E19: Number | F19: 12.5
D20: Linked Cell | E20: Number
D21: Units | E21: Text | F21: Text
D22: Headings 1 | E22: Text | F22: TEXT
D23: Headings 2 | E23: Text | F23: Text
D24: Headings 3 | E24: Text | F24: Text
B27: Revenue Assumptions
C29: Core Revenue Assumptions
D31: Number of Warehouses | E31: units | K31: 510
D32: Total Lettable Space | E32: sqm | K32: 5205000
D33: Square Meters per Store | E33: sqm | K33: =K32/K31 -> 10205.882
D34: Total Revenue | E34: $'m | K34: ='Historicals FS'!I9 -> 1975.48
D35: Auxiliary Revenue | E35: $'m | K35: 143
D36: Core Revenue | E36: $'m | K36: =K34-K35 -> 1832.48
D37: Sales Price per sqm | E37: $ | K37: =K36*million/K32 -> 352.06148
D39: Increase in Sales Price per sqm | E39: % | L39: =Scenarios!L26 -> 0.03 | M39: =Scenarios!M26 -> 0.03 | N39: =Scenarios!N26 -> 0.03 | O39: =Scenarios!O26 -> 0.03 | P39: =Scenarios!P26 -> 0.03
D41: Additional Warehouses | E41: units | L41: =Scenarios!L19 -> 30 | M41: =Scenarios!M19 -> 50 | N41: =Scenarios!N19 -> 55 | O41: =Scenarios!O19 -> 60 | P41: =Scenarios!P19 -> 70
B44: Production Cost Assumptions
D46: Cost of Sales | E46: $'m | K46: ='Historicals FS'!I11 -> 1201.29
D47: Variable Cost | E47: $'m | K47: 0.75
D48: Fixed Cost | E48: $'m | K48: =1-K47 -> 0.25
D49: Variable cost per Warehouse | E49: $'m | K49: =K46*K47/K31 -> 1.7666029
D50: Fixed Cost | E50: $'m | K50: =K46*K48 -> 300.3225
D52: SG& A | E52: $'m | L52: 320
D54: Cost inflation | E54: % | L54: =Scenarios!L33 -> 0.02 | M54: =Scenarios!M33 -> 0.02 | N54: =Scenarios!N33 -> 0.02 | O54: =Scenarios!O33 -> 0.02 | P54: =Scenarios!P33 -> 0.02
B57: Capex & Depreciation Assumptions
C59: Capex
D60: Additions | E60: $'m | L60: 50 | M60: 40 | N60: 50 | O60: 60 | P60: 70
D61: Depreciation Method | E61: Straight Line
...

Sheet Scenarios
B2: =Cover!$C$7 -> Veritas Dwellings | I2: ="Financial Forecast: "&L6&" to "&P6 -> Financial Forecast: 2025 to 2029
B3: Scenario Analysis | I3: =IF(BSCheck=0,"BS Check: OK","BS Check: ERROR") -> BS Check: OK | K3: =ScenarioUSed -> Scenario: Base Case
I5: Actual | J5: Actual | K5: Actual | L5: Forecast | M5: Forecast | N5: Forecast | O5: Forecast | P5: Forecast
E6: Units | F6: Inputs | I6: ='Historicals FS'!G7 -> 2022 | J6: ='Historicals FS'!H7 -> 2023 | K6: ='Historicals FS'!I7 -> 2024 | L6: =K6+1 -> 2025 | M6: =L6+1 -> 2026 | N6: =M6+1 -> 2027 | O6: =N6+1 -> 2028 | P6: =O6+1 -> 2029
B9: Scenario Used
D11: ="Scenario: "&INDEX(L_Scenarios,S_Scenarios) -> Scenario: Base Case | E11: 1
D12: Base Case
D13: Best Case
D14: Worst Case
B17: Additional Warehouses Scenarios
D19: Used in the Model | E19: Units | L19: =INDEX(L20:L22,S_Scenarios) -> 30 | M19: =INDEX(M20:M22,S_Scenarios) -> 50 | N19: =INDEX(N20:N22,S_Scenarios) -> 55 | O19: =INDEX(O20:O22,S_Scenarios) -> 60 | P19: =INDEX(P20:P22,S_Scenarios) -> 70
D20: =D$12 -> Base Case | E20: Units | L20: 30 | M20: 50 | N20: 55 | O20: 60 | P20: 70
D21: =D$13 -> Best Case | E21: Units | L21: 40 | M21: 60 | N21: 65 | O21: 70 | P21: 80
D22: =D$14 -> Worst Case | E22: Units | L22: 20 | M22: 40 | N22: 45 | O22: 50 | P22: 60
B24: Sales Price Inflation Scenarios
D26: Used in the Model | E26: % | L26: =INDEX(L27:L29,S_Scenarios) -> 0.03 | M26: =INDEX(M27:M29,S_Scenarios) -> 0.03 | N26: =INDEX(N27:N29,S_Scenarios) -> 0.03 | O26: =INDEX(O27:O29,S_Scenarios) -> 0.03 | P26: =INDEX(P27:P29,S_Scenarios) -> 0.03
D27: Base Case | E27: % | L27: 0.03 | M27: 0.03 | N27: 0.03 | O27: 0.03 | P27: 0.03
D28: Best Case | E28: % | L28: 0.04 | M28: 0.04 | N28: 0.04 | O28: 0.04 | P28: 0.04
D29: Worst Case | E29: % | L29: 0.02 | M29: 0.02 | N29: 0.02 | O29: 0.02 | P29: 0.02
B31: Cost Inflation Scenario
D33: Used in the Model | E33: % | L33: =INDEX(L34:L36,S_Scenarios) -> 0.02 | M33: =INDEX(M34:M36,S_Scenarios) -> 0.02 | N33: =INDEX(N34:N36,S_Scenarios) -> 0.02 | O33: =INDEX(O34:O36,S_Scenarios) -> 0.02 | P33: =INDEX(P34:P36,S_Scenarios) -> 0.02
D34: Base Case | E34: % | L34: 0.02 | M34: 0.02 | N34: 0.02 | O34: 0.02 | P34: 0.02
D35: Best Case | E35: % | L35: 0.01 | M35: 0.01 | N35: 0.01 | O35: 0.01 | P35: 0.01
D36: Worst Case | E36: % | L36: 0.03 | M36: 0.03 | N36: 0.03 | O36: 0.03 | P36: 0.03

Sheet Model
B2: =Cover!$C$7 -> Veritas Dwellings | I2: ="Financial Forecast: "&L6&" to "&P6 -> Financial Forecast: 2025 to 2029
B3: Model & Schedules | I3: =IF(BSCheck=0,"BS Check: OK","BS Check: ERROR") -> BS Check: OK | K3: =ScenarioUSed -> Scenario: Base Case
I5: Actual | J5: Actual | K5: Actual | L5: Forecast | M5: Forecast | N5: Forecast | O5: Forecast | P5: Forecast
E6: Units | F6: Inputs | I6: ='Historicals FS'!G7 -> 2022 | J6: ='Historicals FS'!H7 -> 2023 | K6: ='Historicals FS'!I7 -> 2024 | L6: =K6+1 -> 2025 | M6: =L6+1 -> 2026 | N6: =M6+1 -> 2027 | O6: =N6+1 -> 2028 | P6: =O6+1 -> 2029
A8: FINANCIAL STATEMENTS
B10: Income Statement
D12: ='Historicals FS'!C9 -> Gross Revenue | E12: $'m | I12: ='Historicals FS'!G9 -> 1553.87 | J12: ='Historicals FS'!H9 -> 1776.88 | K12: ='Historicals FS'!I9 -> 1975.48 | L12: =L146 -> 2145.7711 | M12: =M146 -> 2400.7401 | N12: =N146 -> 2688.7075 | O12: =O146 -> 3012.0125 | P12: =P146 -> 3393.9499
D14: ='Historicals FS'!C11 -> Cost of Sales | E14: $'m | I14: ='Historicals FS'!G11 -> 980.84 | J14: ='Historicals FS'!H11 -> 1078.03 | K14: ='Historicals FS'!I11 -> 1201.29 | L14: =L163 -> 1279.3738 | M14: =M163 -> 1396.86 | N14: =N163 -> 1527.9075 | O14: =O163 -> 1673.1994 | P14: =P163 -> 1843.1964
D15: ='Historicals FS'!C12 -> SG&A | E15: $'m | I15: ='Historicals FS'!G12 -> 265.79 | J15: ='Historicals FS'!H12 -> 290.54 | K15: ='Historicals FS'!I12 -> 305.35 | L15: =L165 -> 320 | M15: =M165 -> 326.4 | N15: =N165 -> 332.928 | O15: =O165 -> 339.58656 | P15: =P165 -> 346.37829
D16: ='Historicals FS'!C13 -> Total Costs | E16: $'m | I16: =SUM(I14:I15) -> 1246.63 | J16: =SUM(J14:J15) -> 1368.57 | K16: =SUM(K14:K15) -> 1506.64 | L16: =SUM(L14:L15) -> 1599.3738 | M16: =SUM(M14:M15) -> 1723.26 | N16: =SUM(N14:N15) -> 1860.8355 | O16: =SUM(O14:O15) -> 2012.7859 | P16: =SUM(P14:P15) -> 2189.5747
D18: ='Historicals FS'!C15 -> Cost Adjustments - Gain/(Loss) | E18: $'m | I18: ='Historicals FS'!G15 -> 0 | J18: ='Historicals FS'!H15 -> 0 | K18: ='Historicals FS'!I15 -> 0 | L18: =Assumptions!L132 -> 0 | M18: =Assumptions!M132 -> 0 | N18: =Assumptions!N132 -> 0 | O18: =Assumptions!O132 -> 0 | P18: =Assumptions!P132 -> 0
D19: ='Historicals FS'!C16 -> EBITDA | E19: $'m | I19: =I12-I16+I18 -> 307.24 | J19: =J12-J16+J18 -> 408.31 | K19: =K12-K16+K18 -> 468.84 | L19: =L12-L16+L18 -> 546.39728 | M19: =M12-M16+M18 -> 677.48014 | N19: =N12-N16+N18 -> 827.87195 | O19: =O12-O16+O18 -> 999.22661 | P19: =P12-P16+P18 -> 1204.3752
D21: ='Historicals FS'!C18 -> Depreciation | E21: $'m | I21: ='Historicals FS'!G18 -> 25.539 | J21: ='Historicals FS'!H18 -> 32.057 | K21: ='Historicals FS'!I18 -> 38.499 | L21: =L187 -> 30.179385 | M21: =M187 -> 32.322242 | N21: =N187 -> 34.4651 | O21: =O187 -> 37.084147 | P21: =P187 -> 40.179385
D22: ='Historicals FS'!C19 -> EBIT | E22: $'m | I22: =I19-I21 -> 281.701 | J22: =J19-J21 -> 376.253 | K22: =K19-K21 -> 430.341 | L22: =L19-L21 -> 516.21789 | M22: =M19-M21 -> 645.15789 | N22: =N19-N21 -> 793.40686 | O22: =O19-O21 -> 962.14246 | P22: =P19-P21 -> 1164.1958
D24: ='Historicals FS'!C21 -> Interest Expense | E24: $'m | I24: ='Historicals FS'!G21 -> 13.304 | J24: ='Historicals FS'!H21 -> 14.263 | K24: ='Historicals FS'!I21 -> 22.055 | L24: =L312 -> 42.724671 | M24: =M312 -> 29.441334 | N24: =N312 -> 9.9110543 | O24: =O312 -> -14.250288 | P24: =P312 -> -44.029926
D25: ='Historicals FS'!C22 -> EBT | E25: $'m | I25: =I22-I24 -> 268.397 | J25: =J22-J24 -> 361.99 | K25: =K22-K24 -> 408.286 | L25: =L22-L24 -> 473.49322 | M25: =M22-M24 -> 615.71656 | N25: =N22-N24 -> 783.4958 | O25: =O22-O24 -> 976.39275 | P25: =P22-P24 -> 1208.2257
D27: ='Historicals FS'!C24 -> Current Taxes | E27: $'m | I27: ='Historicals FS'!G24 -> 62.432 | J27: ='Historicals FS'!H24 -> 92.477 | K27: ='Historicals FS'!I24 -> 100.457 | L27: =L203 -> 151.72263 | M27: =M203 -> 201.5008 | N27: =N203 -> 260.22353 | O27: =O203 -> 327.73746 | P27: =P203 -> 408.879
D28: ='Historicals FS'!C25 -> Deferred Income Taxes | E28: $'m | I28: ='Historicals FS'!G25 -> 9.031 | J28: ='Historicals FS'!H25 -> 2.745 | K28: ='Historicals FS'!I25 -> 10.737 | L28: =L204 -> 14 | M28: =M204 -> 14 | N28: =N204 -> 14 | O28: =O204 -> 14 | P28: =P204 -> 14
D29: ='Historicals FS'!C26 -> Total Income Taxes | E29: $'m | I29: =SUM(I27:I28) -> 71.463 | J29: =SUM(J27:J28) -> 95.222 | K29: =SUM(K27:K28) -> 111.194 | L29: =SUM(L27:L28) -> 165.72263 | M29: =SUM(M27:M28) -> 215.5008 | N29: =SUM(N27:N28) -> 274.22353 | O29: =SUM(O27:O28) -> 341.73746 | P29: =SUM(P27:P28) -> 422.879
D31: ='Historicals FS'!C28 -> Net Income | E31: $'m | I31: =I25-I29 -> 196.934 | J31: =J25-J29 -> 266.768 | K31: =K25-K29 -> 297.092 | L31: =L25-L29 -> 307.7706 | M31: =M25-M29 -> 400.21576 | N31: =N25-N29 -> 509.27227 | O31: =O25-O29 -> 634.65529 | P31: =P25-P29 -> 785.34672
D32: Preference Dividends | E32: $'m | L32: =L252 -> 3.2 | M32: =M252 -> 6.4 | N32: =N252 -> 9.6 | O32: =O252 -> 12.8 | P32: =P252 -> 16
D33: Net Income to Common | E33: $'m | L33: =L31-L32 -> 304.5706 | M33: =M31-M32 -> 393.81576 | N33: =N31-N32 -> 499.67227 | O33: =O31-O32 -> 621.85529 | P33: =P31-P32 -> 769.34672
D35: EBITA Margin | E35: $'m | I35: =I19/I12 -> 0.19772568 | J35: =J19/J12 -> 0.22979042 | K35: =K19/K12 -> 0.23732966 | L35: =L19/L12 -> 0.25463912 | M35: =M19/M12 -> 0.28219636 | N35: =N19/N12 -> 0.30790704 | O35: =O19/O12 -> 0.33174716 | P35: =P19/P12 -> 0.35485945
C36: Dupont Analysis
D37: ROE | E37: $'m | I37: =I31/I114 -> 0.39893204 | J37: =J31/J114 -> 0.85712725 | K37: =K31/K114 -> 4.4437597 | L37: =L31/L114 -> 0.97616957 | M37: =M31/M114 -> 0.63461262 | N37: =N31/N114 -> 0.49665719 | O37: =O31/O114 -> 0.41980347 | P37: =P31/P114 -> 0.37241377
D38: Net Profit Margin | E38: $'m | I38: =I31/I12 -> 0.12673776 | J38: =J31/J12 -> 0.15013282 | K38: =K31/K12 -> 0.15038978 | L38: =L31/L12 -> 0.14343123 | M38: =M31/M12 -> 0.16670516 | N38: =N31/N12 -> 0.18941156 | O38: =O31/O12 -> 0.21070805 | P38: =P31/P12 -> 0.23139609
D39: Asset Turnover | E39: $'m | I39: =I12/I93 -> 1.3639184 | J39: =J12/J93 -> 1.432732 | K39: =K12/K93 -> 1.5489733 | L39: =L12/L93 -> 1.6138316 | M39: =M12/M93 -> 1.7454158 | N39: =N12/N93 -> 1.6739708 | O39: =O12/O93 -> 1.5352803 | P39: =P12/P93 -> 1.3069383
D40: Financial Leverage | E40: $'m | I40: =I93/I114 -> 2.3078336 | J40: =J93/J114 -> 3.9847832 | K40: =K93/K114 -> 19.076044 | L40: =L93/L114 -> 4.2171915 | M40: =M93/M114 -> 2.1810256 | N40: =N93/N114 -> 1.5663989 | O40: =O93/O114 -> 1.2977087 | P40: =P93/P114 -> 1.2314439
B43: Cash Flow Statement
C45: ='Historicals FS'!B36 -> Operating Activities
D46: ='Historicals FS'!C37 -> Net Income | E46: $'m | I46: ='Historicals FS'!G37 -> 196.934 | J46: ='Historicals FS'!H37 -> 266.768 | K46: ='Historicals FS'!I37 -> 297.092 | L46: =L31 -> 307.7706 | M46: =M31 -> 400.21576 | N46: =N31 -> 509.27227 | O46: =O31 -> 634.65529 | P46: =P31 -> 785.34672
D47: ='Historicals FS'!C38 -> Depreciation | E47: $'m | I47: ='Historicals FS'!G38 -> 25.539 | J47: ='Historicals FS'!H38 -> 32.057 | K47: ='Historicals FS'!I38 -> 38.499 | L47: =L21 -> 30.179385 | M47: =M21 -> 32.322242 | N47: =N21 -> 34.4651 | O47: =O21 -> 37.084147 | P47: =P21 -> 40.179385
D48: ='Historicals FS'!C39 -> Deferred Income Taxes | E48: $'m | I48: ='Historicals FS'!G39 -> 9.031 | J48: ='Historicals FS'!H39 -> 2.745 | K48: ='Historicals FS'!I39 -> 10.737 | L48: =L28 -> 14 | M48: =M28 -> 14 | N48: =N28 -> 14 | O48: =O28 -> 14 | P48: =P28 -> 14
D49: ='Historicals FS'!C40 -> Changes in Working Capital | E49: $'m | I49: ='Historicals FS'!G40 -> -5.847 | J49: ='Historicals FS'!H40 -> -19.241 | K49: ='Historicals FS'!I40 -> -2.397 | L49: =L228 -> -61.995582 | M49: =M228 -> -22.01467 | N49: =N228 -> -24.572065 | O49: =O228 -> -26.412414 | P49: =P228 -> -32.762402
D50: Goodwiill Addition/(Impairement) | E50: $'m | L50: =-Assumptions!L134 -> 0 | M50: =-Assumptions!M134 -> 0 | N50: =-Assumptions!N134 -> 0 | O50: =-Assumptions!O134 -> 0 | P50: =-Assumptions!P134 -> 0
D51: ='Historicals FS'!C41 -> Other | E51: $'m | I51: ='Historicals FS'!G41 -> 11.584 | J51: ='Historicals FS'!H41 -> 27.166 | K51: ='Historicals FS'!I41 -> -7.151 | L51: =-Assumptions!L137 -> 0 | M51: =-Assumptions!M137 -> 0 | N51: =-Assumptions!N137 -> 0 | O51: =-Assumptions!O137 -> 0 | P51: =-Assumptions!P137 -> 0
D52: ='Historicals FS'!C42 -> Operating Cash Flow | E52: $'m | I52: =SUM(I46:I51) -> 237.241 | J52: =SUM(J46:J51) -> 309.495 | K52: =SUM(K46:K51) -> 336.78 | L52: =SUM(L46:L51) -> 289.9544 | M52: =SUM(M46:M51) -> 424.52334 | N52: =SUM(N46:N51) -> 533.16531 | O52: =SUM(O46:O51) -> 659.32702 | P52: =SUM(P46:P51) -> 806.7637
C54: ='Historicals FS'!B44 -> Investing Activities
D55: ='Historicals FS'!C45 -> CAPEX | E55: $'m | I55: ='Historicals FS'!G45 -> -56.626 | J55: ='Historicals FS'!H45 -> -62.953 | K55: ='Historicals FS'!I45 -> -110.809 | L55: =-L170 -> -50 | M55: =-M170 -> -40 | N55: =-N170 -> -50 | O55: =-O170 -> -60 | P55: =-P170 -> -70
D56: Intangible Assets | E56: $'m | I56: ='Historicals FS'!G46 -> 0 | J56: ='Historicals FS'!H46 -> 0 | K56: ='Historicals FS'!I46 -> 0 | L56: =-Assumptions!L135 -> 0 | M56: =-Assumptions!M135 -> 0 | N56: =-Assumptions!N135 -> 0 | O56: =-Assumptions!O135 -> 0 | P56: =-Assumptions!P135 -> 0
...
